Workbook

Sheet Welcome Page
C2: STATE UNIVERSAL BASIC EDUCATION BOARD | K2: Insert SUBEB logo here
C3: ANNUAL BASIC EDUCATION ACTION PLAN
B4: State (Select from the drop-down) | C4: BENUE
B5: Activities in this Action plan will be implemented in Year_ (Select from drop-down) | C5: 2025
B6: Action plan to be executed using Matching grants acccessed for year(s) (Specify the matching grant funding year(s) to finance this plan): (e.g 2024) | C6: 2025
B7: Action plan to be executed using Unconditional grants for year (Specify the unconditional grant funding year(s) to finance this plan): (e.g 2024) | C7: 2025 | FM7: Abia
B8: Total matching grant accessed (UBEC + State) (Insert amount in Nigerian Naira) | C8: 7.1092852e+09 | FM8: Adamawa
B9: Total unconditional grants accessed (Insert amount in Nigerian Naira)) | FM9: Adamawa
FM10: Akwa Ibom
B11: INSTRUCTIONS All action plan activities should be informed by the gaps and recommendations from the State's Rapid Assessment tool | CB11: Abia | CC11: 2025 | FM11: Anambra
B12: 1. Itemize and cost all infrastructure projects (construction, renovation, furniture etc.) - A summary of all infrastructure projects and their total costs filled here will appear in Tab: Pillar 1 - Access | FM12: Bauchi
B13: 2. Fill in other details under the applicable column headers under section "Priority 1.1." | CB13: Adamawa | CC13: 2026 | FM13: Bayelsa
B14: 3. Cost all other activities under tab Pillar 1- Access, ensuring each activity is properly organized under the appropriate priority initiatives (1.2 and 1.3) and other enablers sections | FM14: Benue
B15: 4. Develop and cost Sports development activities according to UBEC utilization guidelines - A summary of all Sports Development activities and costs will appear automatically in appropriate section in Tab: Pillar 2 - Quality | FM15: Borno
B16: 5. Outline and cost all Green School and Climate Change Initiative (GSCCI) activities across domains - A summary of all GSCCI activities and costs will appear automatically in the appropriate section in Tab: Pillar 2 - Quality | FM16: Cross River
B17: 6. Complete and cost all other activities under tab: Pillar 2 - Quality, ensuring each activity is properly organized under the appropriate Priority initiatives (2.1, 2.2, 2.3) and other Enablers sections | CB17: Ebonyi | FM17: Delta
B18: 7. Fill in other details under the applicabe column headers under sections "Sports Development" and "Green School and Climate Change Initiative (GSCCI)" in tab: Pillar 2 - Quality | FM18: Ebonyi
B19: 8. Complete and cost all activities under tab Pillar 3 -Systems Optimization, ensuring each activity is properly organized under the appropriate Priority initiatives (3.1, 3.2, 3.3 and 3.4) and the other Enablers sections | FM19: Edo
B20: 9. Conduct a resource mapping for all activities across UBE strategic pillars - ensuring alignment of all available funds across funding sources | CB20: Edo | FM20: Ekiti
CB21: Ekiti | FM21: Enugu
B22: Fill inputs in sheets in the following order below: | CB22: Enugu | FM22: Gombe
B23: Sheet name | C23: Description | CB23: FCT | FM23: Imo
B24: Welcome Page | C24: This is the landing sheet for this tool. It includes the description of sheets and instructions for completing this tool. Fill in the name of your state, action plan year and total matching grant accessed on this sheet Input IS REQUIRED on this sheet | CB24: Gombe | FM24: Jigawa
B25: Infrastructure Projects | C25: This sheet outlines all infrastructure projects planned for the year. It automatically populates the summary of these projects into Priority Initiative 1.1: Provide safe and adequate infrastructure for learning environments on Pillar 1 - Access sheet Outline and cost in all infrastructure projects (construction, renovation, water and sanitation, etc.) on this sheet Input IS REQUIRED on this sheet | FM25: Kaduna
B26: Pillar 1 - Access | C26: This sheet contains all activities aimed at improving access to basic education for the year, organized under the relevant priority initiatives and enablers Outline and cost all activities to improve access to basic education on this sheet Input IS REQUIRED on this sheet | CB26: Kaduna | FM26: Kano
B27: Sports Development | C27: This sheet provides a breakdown of all planned activities for the year across the four thematic utilization guideline areas of the Sports Development Fund. The summary of the entries in this sheet is automatically populated under the Sports Development sections on Pillar 2 - Quality sheet Outline and cost all sports activities on this sheet Input IS REQUIRED on this sheet | FM27: Katsina
B28: Green School and Climate Change and Safeguards (GSCCS) {NEW!} | C28: This sheet provides a breakdown of all planned Green School and Climate Change and Safeguarding activities for the year to enhance the quality of basic education, organized according to the six GSCCS pillars. The summary of inputs for each pillar is automatically populated under GSCCS section on Pillar 2 - Quality sheet. This is a newly revised matching grant domain which replaces AETP on previous template. Outline and cost all GSCCS activities on this sheet Input IS REQUIRED on this sheet | FM28: Kebbi
B29: Pillar 2 - Quality | C29: This sheet contains all activities planned for the year to enhance the quality of teaching and learning in basic education, organized under the relevant priority initiatives and enablers Outline and cost all activities to enhance quality of basic education on this sheet Input IS REQUIRED on this sheet | FM29: Kogi
B30: Pillar 3 - Systems Optimization | C30: This sheet contains all activities planned for the year to optimize basic education systems for quality service delivery, organized under the relevant priority initiatives and enablers Outline and cost all activities to optimize basic education systems on this sheet Input IS REQUIRED on this sheet | FM30: Kwara
B31: Total budget summary & Dashboard | C31: This sheet provides an overview of the budget for each pillar and funding source, as well as the distributions of matching grant formula across formula domains Input IS NOT REQUIRED on this sheet | CB31: Kebbi | FM31: Lagos
B32: DLIs (Disbursement linked indicators) and suggested activities (Project HOPE) | C32: This sheet maps the Project Hope-EDU Disbursement-Linked Indicators (DLIs) to BEAP Pillars, and also includes suggested activities to enabled the state achieve set milestones Input IS NOT REQUIRED on this sheet | CB32: Kwara | FM32: Nasarawa
CB33: Lagos | FM33: Niger
CB34: Nasarawa | FM34: Ogun
CB35: Niger | FM35: Ondo
CB36: Ogun | FM36: Osun
CB37: Ondo | FM37: Oyo
CB38: Osun | FM38: Plateau
CB39: Oyo | FM39: Rivers
CB40: Plateau | FM40: Sokoto
CB41: Rivers | FM41: Taraba
...

Sheet Infrastructure Projects
B2: Click the rows below to go the infrastructure project type you would like to enter
B3: Construction: this includes all consturctions such as new schools, classroom blocks, perimeter fencing, toilets, ICT centres, laboratories, libraries, etc
B4: Renovation: this includes any renovation, upgrade or rehabilitation of an already established structure such as schools, classroom blocks, toilets, etc
B5: Furniture and equipment: this includes procurement of furniture such as desks, chairs, tables, shelves, etc and equipments such as generators, ICT equipments, etc
B6: Water Supply & Sanitation: this includes construction of water supply systems such as boreholes, taps, etc and waste disposal systems such as incinerators, etc
B7: Geophysical Survey: this includes details of the geophysical survey across the recommended locations for sinking of boreholes
B8: Teaching and Learning Materials (TLMs): this includes the list of beneficiary school for distribution of textbooks
I9: GRAND TOTAL INFRASTRUCTURE PROJECTS AND TLMs (No input required) | L9: =U13+U648+P957+P1266+P1421 -> 5.3319639e+09
U12: Total construction cost (No input required)
B13: Construction: this includes all NEW constructions such as new schools, classroom blocks, perimeter fencing, toilets, ICT centres, laboratories, libraries, etc | U13: =SUM(U15,U120,U225,U330,U436,P541) -> 1.2579713e+09
B15: Construction type: | D15: CONSTRUCTION OF UBE STANDARD BLOCK OF 3-CLASSROOMS, OFFICE, STORE AND 6NO. VENTILATED IMPROVED PIT TOILETS | U15: =SUM(T18:T118) -> 2.1905511e+08
B16: S/N | C16: Code | D16: Name of school | E16: LGA | F16: Quantity | G16: Component/Level of School | H16: Location Rural/Urban | I16: Justification for selecting the school (Rationale) | J16: Implementation strategy (Select from the drop-down list) | K16: GPS of school | M16: Duration of construction | N16: Expected output (Please specify quantity) | S16: Unit cost | T16: Total cost (No input required)
K17: Longitude | L17: Latitude | N17: No of classroms | O17: No of playrooms/Labs | P17: No of Libriaries | Q17: No of toilets | R17: No of offices/stores
B18: 1 | C18: UBEC/SUBEB/NC/001/2025 | D18: LGEA Primary School Wailomayo | E18: Makurdi | F18: 1 | G18: ECCDE | H18: Rural | I18: Expanding access to reduce overcrowding | J18: NCB | K18: 6.972923 | L18: 7.923681 | M18: 6 Months | N18: 3 | O18: 0 | P18: 0 | Q18: 6 | R18: 2 | S18: 1.0952756e+08 | T18: =F18*S18 -> 1.0952756e+08
B19: 2 | C19: UBEC/SUBEB/NC/002/2025 | D19: LGEA Primary School Atsor | E19: Gwer East | F19: 1 | G19: JSS | H19: Rural | I19: Expanding access to Basic Education inorder to bring back out-of-school children | J19: NCB | K19: 7.501173 | L19: 8.442443 | M19: 6 Months | N19: 3 | O19: 0 | P19: 0 | Q19: 6 | R19: 2 | S19: 1.0952756e+08 | T19: =F19*S19 -> 1.0952756e+08
B20: 3 | S20: 0 | T20: =F20*S20 -> 0
B21: 4 | S21: 0 | T21: =F21*S21 -> 0
B22: 5 | S22: 0 | T22: =F22*S22 -> 0
B23: 6 | S23: 0 | T23: =F23*S23 -> 0
B24: 7 | S24: 0 | T24: =F24*S24 -> 0
B25: 8 | S25: 0 | T25: =F25*S25 -> 0
B26: 9 | S26: 0 | T26: =F26*S26 -> 0
B27: 10 | S27: 0 | T27: =F27*S27 -> 0
B28: 11 | S28: 0 | T28: =F28*S28 -> 0
B29: 12 | S29: 0 | T29: =F29*S29 -> 0
B30: 13 | S30: 0 | T30: =F30*S30 -> 0
B31: 14 | S31: 0 | T31: =F31*S31 -> 0
... B117: 100 | S117: 0 | T117: =F117*S117 -> 0
D118: Insert new row as necessary above this line | S118: 0 | T118: =F118*S118 -> 0
B120: Construction type | D120: 3NO. BLOCKS OF TWIN COMPARTMENT VENTILATED IMPROVED PIT (VIP) TOILETS | U120: =SUM(T123:T223) -> 1.5171425e+08
B121: S/N | C121: Code | D121: Name of school | E121: LGA | F121: Quantity | G121: Component/Level of School | H121: Location Rural/Urban | I121: Justification for selecting the school (Rationale) | J121: Implementation strategy (Select from the drop-down list) | K121: GPS of school | M121: Duration | N121: Expected output (Please specify quantity) | S121: Unit cost | T121: Total cost (No input required)
K122: Longitude | L122: Latitude | N122: No of classroms | O122: No of playrooms/Labs | P122: No of Libriaries | Q122: No of toilets | R122: No of offices/stores
B123: 1 | C123: UBEC/SUBEB/WS/003/2025 | D123: LGEA Primary School Girgi | E123: Vadeikya | F123: 1 | G123: JSS | H123: Rural | I123: PROVIDE PROPER SANITORY ENVIRONMENT/ADEQUATE WASH FACILITY | J123: Request for quotation | K123: 6.813737 | L123: 9.043157 | M123: 3 MONTHS | N123: 0 | O123: 0 | P123: 0 | Q123: 6 | R123: 0 | S123: 25285708 | T123: =F123*S123 -> 25285708
B124: 2 | C124: UBEC/SUBEB/WS/004/2025 | D124: RCM Primary School Wajir Mbaave | E124: Ushongo | F124: 1 | G124: Primary | H124: Rural | I124: PROVIDE PROPER SANITORY ENVIRONMENT/ADEQUATE WASH FACILITY | J124: Request for quotation | K124: 7.082477 | L124: 9.017949 | M124: 3 MONTHS | N124: 0 | O124: 0 | P124: 0 | Q124: 6 | R124: 0 | S124: 25285708 | T124: =F124*S124 -> 25285708
B125: 3 | C125: UBEC/SUBEB/WS/005/2025 | D125: RCM Primary School Poor | E125: Makurdi | F125: 1 | G125: Primary | H125: Urban | I125: PROVIDE PROPER SANITORY ENVIRONMENT/ADEQUATE WASH FACILITY | J125: Request for quotation | K125: 7.707576 | L125: 8.532451 | M125: 3 MONTHS | N125: 0 | O125: 0 | P125: 0 | Q125: 6 | R125: 0 | S125: 25285708 | T125: =F125*S125 -> 25285708
B126: 4 | C126: UBEC/SUBEB/WS/006/2025 | D126: NKST Primary School Naka | E126: Gwer West | F126: 1 | G126: ECCDE | H126: Rural | I126: PROVIDE PROPER SANITORY ENVIRONMENT/ADEQUATE WASH FACILITY | J126: Request for quotation | K126: 7°34'34" | L126: 8°11'41" | M126: 3 MONTHS | N126: 0 | O126: 0 | P126: 0 | Q126: 6 | R126: 0 | S126: 25285708 | T126: =F126*S126 -> 25285708
B127: 5 | C127: UBEC/SUBEB/WS/007/2025 | D127: LGEA Primary School Ajide Ekeh | E127: Okpokwu | F127: 1 | G127: JSS | H127: Rural | I127: PROVIDE PROPER SANITORY ENVIRONMENT/ADEQUATE WASH FACILITY | J127: Request for quotation | K127: 7.01094 | L127: 7.85102 | M127: 3 MONTHS | N127: 0 | O127: 0 | P127: 0 | Q127: 6 | R127: 0 | S127: 25285708 | T127: =F127*S127 -> 25285708
B128: 6 | C128: UBEC/SUBEB/WS/008/2025 | D128: St Mary’s Pilot Primary School, Ogobia Ugboju | E128: Otukpo | F128: 1 | G128: ECCDE | H128: Urban | I128: PROVIDE PROPER SANITORY ENVIRONMENT/ADEQUATE WASH FACILITY | J128: Request for quotation | K128: 7.18991 | L128: 8.36891 | M128: 3 MONTHS | N128: 0 | O128: 0 | P128: 0 | Q128: 6 | R128: 0 | S128: 25285708 | T128: =F128*S128 -> 25285708
B129: 7 | S129: 0 | T129: =F129*S129 -> 0
B130: 8 | S130: 0 | T130: =F130*S130 -> 0
...

Sheet Description of sheets
B2: Sheet name | C2: Description
B3: Welcome Page | C3: This is the landing sheet for this tool. It includes the instructions for completing this tool. Fill in the name of your state and the action plan year on this sheet. INPUT IS REQUIRED ON THIS SHEET
B4: Description of sheets | C4: This sheet describes all the other sheets on this tool. NO INPUT REQUIRED ON THIS SHEET
B5: Unit Cost Set-Up | C5: This sheet includes all the unit costs required for costing activities. Update the sheet frequently with cost items and their unit costs. INPUT REQUIRED ON THIS SHEET
B6: Pillar 1,2,3 | C6: This sheet is where all the activities to be carried out in the year are listed, categorized under the relevant pillar and priority initiative. INPUT REQUIRED ON THIS SHEET
B7: Infrastructure Projects | C7: This sheet provides a break down of all infrastructure projects planned for the year. INPUT REQUIRED ON THIS SHEET
B8: Activity costing | C8: All activities listed under the Pillar 1,2,3 sheets should be costed here. INPUT REQUIRED ON THIS SHEET
B9: Total budget summary | C9: This sheet provides and overview of the budget for each pillar, the funding source and the funding gap. INPUT REQUIRED ON THIS SHEET
B10: Dashboard | C10: This sheet includes visualization the budget summary for each pillar and trackes the implementation status of activities. It is usefule during action plan review meetings NO INPUT REQUIRED ON THIS SHEET

Sheet Pillar 1 - Access
B2: Click to return to welcome page
B4: Pillar 1: Expand access to UBE especially for rural and underserved populations
H6: HOPE-DLI | I6: UBE Pillar
C7: Click to move to each sub-theme/sections
C8: Priority initiative 1.1: Provide safe and adequate infrastructure for learning environments
C9: Priority initiative 1.2: Expand enrollment of out-of-school children into the formal education system
C10: Priority initiative 1.3: Improve retention with incentives such as School-based management committee initiatives
C11: Enabler (Matching grant): Supervision and Project monitoring of ongoing infrastructure activities
C12: Enabler: Partnerships and cross-sector collaboration to expand access to basic education
C14: S/N | D14: Focus | E14: Activity (No input is required/autogenerated from infrastructure projects) | F14: Total quantity required (from needs assessment) | G14: Total quantity planned (No input required) | H14: Target group (Select from the drop-down) | I14: Number of expected beneficiaries | J14: Expected output/Deliverable | K14: Timeline/Duration | L14: Expected start date MM-DD-YYYY | M14: Expected due date MM-DD-YYYY | N14: Achievement indicator (% of project completed) | O14: Total cost (No input required) | P14: Implementation strategy (Select from the drop-down list) | Q14: Resource mapping | X14: Infrastructure Gap (No input required) | Y14: Funding gap (No input required) | Z14: Remarks
Q15: Government fund | T15: Development partner 1 | V15: Development partner 2
Q16: State Government education budget | R16: UBEC+State matching grant | S16: Unconditional grants/Emergency funds | T16: Name | U16: Amount | V16: Name | W16: Amount
C17: Priority initiative 1.1: Provide safe and adequate infrastructure for learning environments (Hope-EDU DLI)
C18: Objective: To enhance access to education for children in a conducive, safe and modern environment to enhance effective teaching, learning and administration
C19: 1.1.1 | D19: Construction | E19: ='Infrastructure Projects'!D15 -> CONSTRUCTION OF UBE STANDARD BLOCK OF 3-CLASSROOMS, OFFICE, STORE AND 6NO. VENTILATED IMPROVED PIT TOILETS | F19: 2401 | G19: =SUM('Infrastructure Projects'!F18:F118) -> 2 | H19: Primary School Learners and Teachers | I19: 240 | J19: 6 Classrooms, 2 Offices, 2 Stores and 12 Toilets will be delivered | K19: 6 Months | L19: 45962 | M19: 46053 | N19: 100% Project completion | O19: ='Infrastructure Projects'!U15 -> 2.1905511e+08 | P19: NCB | Q19: 0 | R19: 2.1905511e+08 | S19: 0 | U19: 0 | W19: 0 | X19: =(F19-G19) -> 2399 | Y19: =O19-(Q19+R19+S19+U19+W19) -> 0
C20: 1.1.2 | E20: ='Infrastructure Projects'!D120 -> 3NO. BLOCKS OF TWIN COMPARTMENT VENTILATED IMPROVED PIT (VIP) TOILETS | F20: 397 | G20: =SUM('Infrastructure Projects'!F123:F223) -> 6 | H20: Primary School Learners and Teachers | I20: 2732 | J20: 36 Toilets will be delivered | K20: 6 Months | L20: 45962 | M20: 46053 | N20: 100% Project completion | O20: ='Infrastructure Projects'!U120 -> 1.5171425e+08 | P20: Request for quotation | Q20: 0 | R20: 1.5171425e+08 | S20: 0 | U20: 0 | W20: 0 | X20: =(F20-G20) -> 391 | Y20: =O20-(Q20+R20+S20+U20+W20) -> 0
C21: 1.1.3 | E21: ='Infrastructure Projects'!D225 -> 0 | G21: =SUM('Infrastructure Projects'!F228:F328) -> 0 | J21: 6 Classrooms, 2 Offices, 2 Stores and 12 Toilets will be delivered | M21: 46053 | O21: ='Infrastructure Projects'!U225 -> 0 | Q21: 0 | R21: 0 | S21: 0 | U21: 0 | W21: 0 | X21: =(F21-G21) -> 0 | Y21: =O21-(Q21+R21+S21+U21+W21) -> 0
C22: 1.1.4 | E22: ='Infrastructure Projects'!D330 -> 0 | G22: =SUM('Infrastructure Projects'!F333:F433) -> 0 | J22: 6 Classrooms, 2 Offices, 2 Stores and 12 Toilets will be delivered | M22: 46053 | O22: ='Infrastructure Projects'!U330 -> 0 | Q22: 0 | R22: 0 | S22: 0 | U22: 0 | W22: 0 | X22: =(F22-G22) -> 0 | Y22: =O22-(Q22+R22+S22+U22+W22) -> 0
C23: 1.1.5 | E23: ='Infrastructure Projects'!D436 -> 0 | G23: =SUM('Infrastructure Projects'!F439:F539) -> 0 | J23: 6 Classrooms, 2 Offices, 2 Stores and 12 Toilets will be delivered | M23: 46053 | O23: ='Infrastructure Projects'!U436 -> 0 | Q23: 0 | R23: 0 | S23: 0 | U23: 0 | W23: 0 | X23: =(F23-G23) -> 0 | Y23: =O23-(Q23+R23+S23+U23+W23) -> 0
C24: 1.1.6 | E24: ='Infrastructure Projects'!D541 -> CONSTRUCTION OF PERIMETER FENCE AND GATE HOUSE | F24: 3920400 | G24: =SUM('Infrastructure Projects'!F544:F644) -> 5756 | H24: All Learners and Teachers | I24: 3212 | J24: 5,171M perimeter fences, 8 Gatehouses, external works, 8 Toilets, Purpose made steel Metal grille and galvanised razoor fence Concertina wire will be delivered | K24: 6 Months | L24: 45962 | M24: 46053 | N24: 100% Project completion | O24: ='Infrastructure Projects'!P541 -> 8.8720192e+08 | P24: NCB | Q24: 0 | R24: 8.0945803e+08 | S24: 0 | U24: 0 | W24: 0 | X24: =(F24-G24) -> 3914644 | Y24: =O24-(Q24+R24+S24+U24+W24) -> 77743891 | Z24: THE NUMBER OF PERIMETER FENCE IS IN METERS SO ITS DIFFICULT TO ESTIMATE
C25: 1.1.7 | D25: Renovation | E25: ='Infrastructure Projects'!D649 -> Reha/Renovation of Classrooms, Offices, Stores, Libraries and Toilets (Whole School Approach). | F25: 502 | G25: =SUM('Infrastructure Projects'!F652:F762) -> 9 | H25: All Learners and Teachers | I25: 3280 | J25: 79 Classrooms, 3 Playrooms, 1 Library, 13 Offices, 13 Stores and 24 Toilets will be delivered | K25: 6 Months | L25: 45962 | M25: 46053 | N25: 100% Project completion | O25: ='Infrastructure Projects'!U649 -> 1.2463821e+09 | P25: NCB | Q25: 0 | R25: 1.2463821e+09 | S25: 0 | U25: 0 | W25: 0 | X25: =(F25-G25) -> 493 | Y25: =O25-(Q25+R25+S25+U25+W25) -> 0
C26: 1.1.8 | D26: Furniture and equipment | E26: ='Infrastructure Projects'!D958 -> EQUIPMENT; COMPUTERS IN DIGITAL LIBRARIES, FURNITURE; CONSTRUCTION OF 2-SEATER DUAL-DESK OF STEEL/WOOD | F26: 335760 | G26: =SUM('Infrastructure Projects'!F961:F1261) -> 3115 | H26: All Learners and Teachers | I26: 6572 | J26: 3,286No. equipment; computers in digital libraries, furniture; fabricated 2-seater dual-desk of steel/wood will be delivered | K26: 3 Months | L26: 45962 | M26: 46053 | N26: 100% Project completion | O26: ='Infrastructure Projects'!P958 -> 1.8503095e+09 | P26: NCB | Q26: 0 | R26: 1.9272794e+09 | S26: 0 | U26: 0 | W26: 0 | X26: =(F26-G26) -> 332645 | Y26: =O26-(Q26+R26+S26+U26+W26) -> -76969891
C27: 1.1.9 | D27: Water Supply & Sanitation (including Geophysical survey) | E27: ='Infrastructure Projects'!D1267 -> DRILLING OF MOTORIZED BOREHOLES WITH OVERHEAD STEEL STANCTION, 4000L PVC TANK AND INSTALLATION OF SOLAR RACK/PUMPS | F27: 3268 | G27: ='Infrastructure Projects'!P1266 -> 255675000 | H27: All Learners and Teachers | I27: 4282 | J27: 10 motorized boreholes with overhead steel stanction, 4000l pvc tank and installation of solar rack/pumps will be delivered | K27: 3 Months | L27: 45962 | M27: 46053 | N27: 100% Project completion | O27: ='Infrastructure Projects'!P1267 -> 254000000 | P27: Request for quotation | Q27: 0 | R27: 250000000 | S27: 0 | U27: 0 | W27: 0 | X27: =(F27-G27) -> -255671732 | Y27: =O27-(Q27+R27+S27+U27+W27) -> 4000000
D28: TOTAL | O28: =SUM(O19:O27) -> 4.6086629e+09 | Q28: =SUM(Q19:Q27) -> 0 | R28: =SUM(R19:R27) -> 4.6038889e+09 | S28: =SUM(S19:S27) -> 0 | T28: =SUM(U19:U27,W19:W27) -> 0 | Y28: =SUM(Y19:Y27) -> 4774000
C30: S/N | D30: Activity | E30: Rationale/Reason for choice of activity | F30: Quantity | G30: Expected output | H30: Number of expected beneficiaries (OOSC) | I30: Target group (Select from the drop-down) | J30: Timeline (Shade as applicable) | N30: Expected due date MM-DD-YYYY | O30: Achievement indicator (% of project completed) | P30: Unit cost | Q30: Total cost (No input required) | R30: Implementation strategy (Select from the drop-down list) | S30: Resource mapping | Z30: Funding gap (No input required) | AA30: Remarks
S31: Government fund | V31: Development partner 1 | X31: Development partner 2
J32: Q1 | K32: Q2 | L32: Q3 | M32: Q4 | S32: State Government education budget | T32: UBEC matching grant | U32: Unconditional grants/Emergency funds | V32: Name | W32: Amount | X32: Name | Y32: Amount | Z32: (No input required)
C33: Priority initiative 1.2: Expand enrollment of out-of-school children into the formal education system (Hope-EDU DLI)
C34: Objective: Reintegrate out of school children and increase enrolment to improve access to education
C35: 1.2.Ex | D35: Implement open school activities in nomadic and high density IDP camps across 3 LGAs | E35: High number of OOSC children due to conflict | F35: 9 | G35: 9 Informal schools established across 9 IDP camps | H35: 540 OOSC children reintegrated | I35: Primary School Learners | N35: 05-21-2025 | O35: 100% of informal schools established in selected IDP camps | Q35: =F35*P35 -> 0 | S35: 0 | V35: UNICEF | Y35: 0 | Z35: =Q35-(S35+T35+U35+W35+Y35) -> 0
C36: 1.2.1 | P36: 0 | Q36: =F36*P36 -> 0 | S36: 0 | T36: 0 | U36: 0 | W36: 0 | Y36: 0 | Z36: =Q36-(S36+T36+U36+W36+Y36) -> 0
C37: 1.2.2 | P37: 0 | Q37: =F37*P37 -> 0 | S37: 0 | T37: 0 | U37: 0 | W37: 0 | Y37: 0 | Z37: =Q37-(S37+T37+U37+W37+Y37) -> 0
C38: 1.2.3 | P38: 0 | Q38: =F38*P38 -> 0 | S38: 0 | T38: 0 | U38: 0 | W38: 0 | Y38: 0 | Z38: =Q38-(S38+T38+U38+W38+Y38) -> 0
C39: 1.2.4 | P39: 0 | Q39: =F39*P39 -> 0 | S39: 0 | T39: 0 | U39: 0 | W39: 0 | Y39: 0 | Z39: =Q39-(S39+T39+U39+W39+Y39) -> 0
C40: 1.2.5 | P40: 0 | Q40: =F40*P40 -> 0 | S40: 0 | T40: 0 | U40: 0 | W40: 0 | Y40: 0 | Z40: =Q40-(S40+T40+U40+W40+Y40) -> 0
C41: 1.2.6 | P41: 0 | Q41: =F41*P41 -> 0 | S41: 0 | T41: 0 | U41: 0 | W41: 0 | Y41: 0 | Z41: =Q41-(S41+T41+U41+W41+Y41) -> 0
C42: 1.2.7 | P42: 0 | Q42: =F42*P42 -> 0 | S42: 0 | T42: 0 | U42: 0 | W42: 0 | Y42: 0 | Z42: =Q42-(S42+T42+U42+W42+Y42) -> 0
C43: 1.2.8 | P43: 0 | Q43: =F43*P43 -> 0 | S43: 0 | T43: 0 | U43: 0 | W43: 0 | Y43: 0 | Z43: =Q43-(S43+T43+U43+W43+Y43) -> 0
C44: 1.2.9 | P44: 0 | Q44: =F44*P44 -> 0 | S44: 0 | T44: 0 | U44: 0 | W44: 0 | Y44: 0 | Z44: =Q44-(S44+T44+U44+W44+Y44) -> 0
C45: 1.2.10 | P45: 0 | Q45: =F45*P45 -> 0 | S45: 0 | T45: 0 | U45: 0 | W45: 0 | Y45: 0 | Z45: =Q45-(S45+T45+U45+W45+Y45) -> 0
...

Sheet Sports Development
A2: S/N | B2: Click the rows below to go the sports pillars type you would like to enter
A3: 1 | B3: Procurement of sports equipments
A4: 2 | B4: Sports Competitions
A5: 3 | B5: Publicity and Administrations
A6: 4 | B6: Supervision, Assessment and Verification
A7: 5 | B7: Annexus: List of beneficiary schools for sports equipment
G9: Total Procurement cost
B10: 1 | C10: Procurement of sport equipments | H10: =SUM(H11+H36+H61+H86+H111) -> 86644756
B11: 1.A.Type of Sport/Game: FOOTBAL | H11: =SUM(G14:G34) -> 46015762
B12: S/N | C12: Code | D12: Item description | E12: Qty | F12: Unit cost | G12: Total cost (No input required)
B14: 1 | C14: UBEC/SUBEB/SP/001-023/2025 | D14: Construction of mini-football fields (grass) with Installation of galvanize iron pipe goal post with improved 400m running tracks in selected schools | E14: 23 | F14: 2000685.3 | G14: =E14*F14 -> 46015762
G15: =E15*F15 -> 0
B16: 3 | F16: 0 | G16: =E16*F16 -> 0
B17: 4 | F17: 0 | G17: =E17*F17 -> 0
B18: 5 | F18: 0 | G18: =E18*F18 -> 0
B19: 6 | F19: 0 | G19: =E19*F19 -> 0
B20: 7 | F20: 0 | G20: =E20*F20 -> 0
B21: 8 | F21: 0 | G21: =E21*F21 -> 0
B22: 9 | F22: 0 | G22: =E22*F22 -> 0
B23: 10 | F23: 0 | G23: =E23*F23 -> 0
B24: 11 | F24: 0 | G24: =E24*F24 -> 0
B25: 12 | F25: 0 | G25: =E25*F25 -> 0
B26: 13 | F26: 0 | G26: =E26*F26 -> 0
B27: 14 | F27: 0 | G27: =E27*F27 -> 0
... B33: 20 | F33: 0 | G33: =E33*F33 -> 0
D34: Insert new row as necessary above this line | F34: 0 | G34: =E34*F34 -> 0
B36: 1.B. Type of Sport/Game: CHESS | H36: =SUM(G39:G59) -> 2300000
B37: S/N | C37: Code | D37: Item description | E37: Qty | F37: Unit cost | G37: Total cost (No input required)
B39: 1 | C39: UBEC/SUBEB/SP/024-115/2025 | D39: Chess game (4 per school) | E39: 92 | F39: 25000 | G39: =E39*F39 -> 2300000
B40: 2 | F40: 0 | G40: =E40*F40 -> 0
B41: 3 | F41: 0 | G41: =E41*F41 -> 0
B42: 4 | F42: 0 | G42: =E42*F42 -> 0
B43: 5 | F43: 0 | G43: =E43*F43 -> 0
B44: 6 | F44: 0 | G44: =E44*F44 -> 0
B45: 7 | F45: 0 | G45: =E45*F45 -> 0
B46: 8 | F46: 0 | G46: =E46*F46 -> 0
B47: 9 | F47: 0 | G47: =E47*F47 -> 0
B48: 10 | F48: 0 | G48: =E48*F48 -> 0
B49: 11 | F49: 0 | G49: =E49*F49 -> 0
B50: 12 | F50: 0 | G50: =E50*F50 -> 0
...

Sheet GSCCS
B3: Click the rows below to go the Green School and Climate Change and Safeguards (GSCCS) pillar type you would like to enter
B4: GSCCI Pillar 1: Greening schools/planting of trees
B5: GSCCI Pillar 2: Promoting entrepreneurial Greening curricula
B6: GSCCI Pillar 3: Teacher training and education system capacity
B7: GSCCI Pillar 4: Greening communities
B8: GSCCI Pillar 5: National Greening competitions
B9: GSCCI Pillar 6: Establishment of Green Clubs (Climate change clubs)
B10: Rearing of Small Animals/Aquatic Farming
B11: Safeguards and Waste Management Initiatives
B12: Supervision and monitoring of GSCCS initiatives | P12: GSCCS GRAND TOTAL | Q12: =SUM(P14,P62,P110,P158,P206,P254,P302,P373,P443) -> 1.421857e+08
P13: Total Cost: GSCCI Pillar 1 (No input required)
B14: GSCCI Pillar 1: Greening schools/planting of trees | P14: =SUM(P18:P58) -> 29999296
B15: Objective:
B16: S/N | C16: Activity/item description | D16: Quantity (Insert only numeric values) | E16: Name of School | F16: LGA | G16: Location (Rural/Urban) | H16: GPS coordinates | J16: Enterprise Code | K16: Target Group (Select from the drop-down) | L16: Implementation strategy (Select from the drop-down) | M16: Duration | N16: Expected outcome | O16: Unit cost | P16: Total cost (No input required) | Q16: Remark
H17: Longitude | I17: Latitude
B18: 1 | C18: Planting of Palm Trees | D18: 20 | E18: LGEA Primary School Igirgi | F18: VANDEIKYA | G18: Rural | H18: 6.813737 | I18: 9.043157 | J18: UBEC/SUBEB/GSCCI/2025/001 | K18: All Learners and Teachers | L18: Credit School account | M18: 4 Weeks | N18: 20 palm trees planted | O18: 37499.12 | P18: =D18*O18 -> 749982.4
B19: 2 | C19: Planting of Palm Trees | D19: 20 | E19: RCM Primary School Poor | F19: MAKURDI | G19: Urban | H19: 7.707576 | I19: 8.532451 | J19: UBEC/SUBEB/GSCCI/2025/002 | K19: All Learners and Teachers | L19: Credit School account | M19: 4 Weeks | N19: 20 palm trees planted | O19: 37499.12 | P19: =D19*O19 -> 749982.4
B20: 3 | C20: Planting of Palm Trees | D20: 20 | E20: RCM Primary School Ugye | F20: VANDEIKYA | G20: Rural | H20: 6.75072 | I20: 9.26667 | J20: UBEC/SUBEB/GSCCI/2025/003 | K20: All Learners and Teachers | L20: Credit School account | M20: 4 Weeks | N20: 20 palm trees planted | O20: 37499.12 | P20: =D20*O20 -> 749982.4
B21: 4 | C21: Planting of Palm Trees | D21: 20 | E21: LGEA PRIMARY SCHOOL ORNGUDUEM-MBATIAV | F21: GBOKO | G21: Rural | H21: 7.324427 | I21: 8.745795 | J21: UBEC/SUBEB/GSCCI/2025/004 | K21: All Learners and Teachers | L21: Credit School account | M21: 4 Weeks | N21: 20 palm trees planted | O21: 37499.12 | P21: =D21*O21 -> 749982.4
B22: 5 | C22: Planting of Palm Trees | D22: 20 | E22: LGEA Primary School, Mbakunde | F22: VANDEIKYA | G22: Rural | H22: 6.80222 | I22: 9.030277 | J22: UBEC/SUBEB/GSCCI/2025/005 | K22: All Learners and Teachers | L22: Credit School account | M22: 4 Weeks | N22: 20 palm trees planted | O22: 37499.12 | P22: =D22*O22 -> 749982.4
B23: 6 | C23: Planting of Palm Trees | D23: 20 | E23: LGEA Primary School Effiom Edumoga | F23: OKPOKWU | G23: Rural | H23: 6.972923 | I23: 7.923681 | J23: UBEC/SUBEB/GSCCI/2025/006 | K23: All Learners and Teachers | L23: Credit School account | M23: 4 Weeks | N23: 20 palm trees planted | O23: 37499.12 | P23: =D23*O23 -> 749982.4
B24: 7 | C24: Planting of Palm Trees | D24: 20 | E24: LGEA PRIMARY SCHOOL AYAR-MBALOM | F24: GWER | G24: Rural | H24: 7.501173 | I24: 8.442443 | J24: UBEC/SUBEB/GSCCI/2025/007 | K24: All Learners and Teachers | L24: Credit School account | M24: 4 Weeks | N24: 20 palm trees planted | O24: 37499.12 | P24: =D24*O24 -> 749982.4
B25: 8 | C25: Planting of Palm Trees | D25: 20 | E25: NKST PRIMARY SCHOOL ATUKPU | F25: GWER WEST | G25: Rural | H25: 7.551713 | I25: 8.1949462 | J25: UBEC/SUBEB/GSCCI/2025/008 | K25: All Learners and Teachers | L25: Credit School account | M25: 4 Weeks | N25: 20 palm trees planted | O25: 37499.12 | P25: =D25*O25 -> 749982.4
B26: 9 | C26: Planting of Palm Trees | D26: 20 | E26: LGEA SCIENCE PRIMARY SCHOOL TORDONGA | F26: KATSIN ALA | G26: Rural | H26: 7.23451 | I26: 9.64793 | J26: UBEC/SUBEB/GSCCI/2025/009 | K26: All Learners and Teachers | L26: Credit School account | M26: 4 Weeks | N26: 20 palm trees planted | O26: 37499.12 | P26: =D26*O26 -> 749982.4
B27: 10 | C27: Planting of Palm Trees | D27: 20 | E27: RCM PRIMARY SCHOOL ACHU | F27: GWER WEST | G27: Rural | H27: 7.43088 | I27: 8.15606 | J27: UBEC/SUBEB/GSCCI/2025/010 | K27: All Learners and Teachers | L27: Credit School account | M27: 4 Weeks | N27: 20 palm trees planted | O27: 37499.12 | P27: =D27*O27 -> 749982.4
B28: 11 | C28: Planting of Palm Trees | D28: 20 | E28: RCM PRIMARY SCHOOL TSE-TWAR | F28: KATSIN ALA | G28: Rural | H28: 7.459672 | I28: 9.447688 | J28: UBEC/SUBEB/GSCCI/2025/011 | K28: All Learners and Teachers | L28: Credit School account | M28: 4 Weeks | N28: 20 palm trees planted | O28: 37499.12 | P28: =D28*O28 -> 749982.4
B29: 12 | C29: Planting of Palm Trees | D29: 20 | E29: NKST UBE JSS TONGO | F29: KONSHISHA | G29: Rural | H29: 6.57288 | I29: 8.46406 | J29: UBEC/SUBEB/GSCCI/2025/012 | K29: All Learners and Teachers | L29: Credit School account | M29: 4 Weeks | N29: 20 palm trees planted | O29: 37499.12 | P29: =D29*O29 -> 749982.4
... B57: 40 | C57: Planting of Palm Trees | D57: 20 | E57: LGEA PRIMARY SCHOOL EFFE UGBOKOLO | F57: OKPOKWU | G57: Urban | H57: 7.191622 | I57: 7.7464893 | J57: UBEC/SUBEB/GSCCI/2025/040 | K57: All Learners and Teachers | L57: Credit School account | M57: 4 Weeks | N57: 20 palm trees planted | O57: 37499.12 | P57: =D57*O57 -> 749982.4
C58: Insert new row as necessary above this line | O58: 0 | P58: =D58*O58 -> 0
P61: Total Cost: GSCCI Pillar 2 (No input required)
B62: GSCCI Pillar 2: Promoting entrepreneurial Greening curricula | P62: =SUM(P66:P106) -> 1501856.8
B63: Objective:
B64: S/N | C64: Activity/item description | D64: Quantity (Insert only numeric values) | E64: Name of School | F64: LGA | G64: Location (Rural/Urban) | H64: GPS coordinates | J64: Enterprise Code | K64: Target Group (Select from the drop-down) | L64: Implementation strategy (Select from the drop-down) | M64: Duration | N64: Expected outcome | O64: Unit cost | P64: Total cost (No input required) | Q64: Remark
H65: Longitude | I65: Latitude
B66: 1 | C66: Procurement of greening curriculum guide | D66: 1 | E66: LGEA Primary School Igirgi | F66: VANDEIKYA | G66: Rural | H66: 6.813737 | I66: 9.043157 | J66: UBEC/SUBEB/GSCCI/2025/041 | K66: All Learners and Teachers | L66: Request for quotation | M66: 12 Weeks | N66: 1 Greening curriculum guide will be delivered | O66: 37546.42 | P66: =D66*O66 -> 37546.42
B67: 2 | C67: Procurement of greening curriculum guide | D67: 1 | E67: RCM Primary School Poor | F67: MAKURDI | G67: Urban | H67: 7.707576 | I67: 8.532451 | J67: UBEC/SUBEB/GSCCI/2025/042 | K67: All Learners and Teachers | L67: Request for quotation | M67: 12 Weeks | N67: 1 Greening curriculum guide will be delivered | O67: 37546.42 | P67: =D67*O67 -> 37546.42
B68: 3 | C68: Procurement of greening curriculum guide | D68: 1 | E68: RCM Primary School Ugye | F68: VANDEIKYA | G68: Rural | H68: 6.75072 | I68: 9.26667 | J68: UBEC/SUBEB/GSCCI/2025/043 | K68: All Learners and Teachers | L68: Request for quotation | M68: 12 Weeks | N68: 1 Greening curriculum guide will be delivered | O68: 37546.42 | P68: =D68*O68 -> 37546.42
B69: 4 | C69: Procurement of greening curriculum guide | D69: 1 | E69: LGEA PRIMARY SCHOOL ORNGUDUEM-MBATIAV | F69: GBOKO | G69: Rural | H69: 7.324427 | I69: 8.745795 | J69: UBEC/SUBEB/GSCCI/2025/044 | K69: All Learners and Teachers | L69: Request for quotation | M69: 12 Weeks | N69: 1 Greening curriculum guide will be delivered | O69: 37546.42 | P69: =D69*O69 -> 37546.42
B70: 5 | C70: Procurement of greening curriculum guide | D70: 1 | E70: LGEA Primary School, Mbakunde | F70: VANDEIKYA | G70: Rural | H70: 6.80222 | I70: 9.030277 | J70: UBEC/SUBEB/GSCCI/2025/045 | K70: All Learners and Teachers | L70: Request for quotation | M70: 12 Weeks | N70: 1 Greening curriculum guide will be delivered | O70: 37546.42 | P70: =D70*O70 -> 37546.42
B71: 6 | C71: Procurement of greening curriculum guide | D71: 1 | E71: LGEA Primary School Effiom Edumoga | F71: OKPOKWU | G71: Rural | H71: 6.972923 | I71: 7.923681 | J71: UBEC/SUBEB/GSCCI/2025/046 | K71: All Learners and Teachers | L71: Request for quotation | M71: 12 Weeks | N71: 1 Greening curriculum guide will be delivered | O71: 37546.42 | P71: =D71*O71 -> 37546.42
...

Sheet Pillar 2 - Quality
B2: Click to return to welcome page
B4: Pillar 2: Enhance Quality of Teaching and Learning
G7: HOPE-DLI | H7: UBE Pillar
C8: Click to move to each sub-theme/section
C9: Priority initiative 2.1 (Matching grant): Ensure implementation of revised basic education curriculum across schools
C10: Priority initiative 2.2: Provision of adequate Teaching and Learning Materials (TLMs) for schools
C11: Priority initiative 2.3: Teacher/ education managers training and capacity building
C12: Enabler-matching grant Intervention: Quality Assurance monitoring (other)
C13: Enabler-matching grant: Levergaing digitalization to improve quality of basic education (ICT and Data Platform)
C14: Matching Grant Intervention: Sports Development
C15: Enabler-matching Grant Intervention: Green School and Climate Change and Safeguards (GSCCS)
C17: S/N | D17: Activity | E17: Objective | F17: Quantity | G17: Expected output | H17: Achievement indicator (% of activity completed) | I17: Target group (Select from the drop-down) | J17: Timeline (Shade as applicable) | N17: Expected start date MM-DD-YYYY | O17: Expected due date MM-DD-YYYY | P17: Unit cost | Q17: Total cost (No input required) | R17: Implementation strategy (Select from the drop-down list) | S17: Resource mapping | Z17: Funding gap (No input required) | AA17: Remarks
S18: Government fund | V18: Development partner 1 | X18: Development partner 2
J19: Q1 | K19: Q2 | L19: Q3 | M19: Q4 | S19: State education budget | T19: UBEC matching grant | U19: Unconditional grants/Emergency funds | V19: Name | W19: Amount | X19: Name | Y19: Amount
C20: Priority initiative 2.1 (Matching grant): Ensure implementation of revised basic education curriculum across schools
C21: 2.1.1 | D21: Purchase of 12000 copies of revised Basic education curriculum from NERDC: 50% public and 20% private schools respectively) | E21: In accordance with the Nigerian Educational Research and Development Council's (NERDC) standards, to guarantee that all public basic education schools in the state have access to the most up-to-date, nationally recognized curriculum materials in order to support consistent, pertinent, and competency-based teaching and learning. | F21: 12000 | G21: Widespread distribution and use of standardized, up-to-date curriculum materials across public basic education schools in the state, enabling consistent, competency-based teaching and improved instructional planning. | H21: 12000 curriculum purchased | I21: State level | N21: 45962 | O21: 45688 | P21: 8294.166 | Q21: =F21*P21 -> 99529992 | R21: Single source/Direct contracting | S21: 0 | T21: 99529992 | U21: 0 | W21: 0 | Y21: 0 | Z21: =Q21-SUM(S21:U21, W21,Y21) -> 0.00056791306
C22: 2.1.2 | D22: Distribution of 12000 copies of revised Basic education curriculum from NERDC to basic schools in 23 LGAs | E22: All public basic education schools in the 23 Local Government Areas (LGAs) of Benue State must have broad access to the nationally updated curriculum in order to standardize teaching materials, enhance instructional design, and improve learning outcomes in accordance with NERDC and UBEC guidelines. | F22: 23 | G22: All public basic education schools across the 23 LGAs are equipped with the updated NERDC curriculum, enabling standardized, quality-driven teaching and learning statewide | H22: 12000 Curriculum distributed | I22: State level | N22: 45962 | O22: 45688 | P22: 309099.36 | Q22: =F22*P22 -> 7109285.2 | R22: E-payment/Cash transfer | S22: 0 | T22: 7109285.2 | U22: 0 | W22: 0 | Y22: 0 | Z22: =Q22-SUM(S22:U22, W22,Y22) -> -0.00100007
C23: 2.1.3 | D23: Curriculum Orientation and sensitization campaigns at the three senatorial zones in the State | E23: To enhance effective implementation of the curriculum | F23: 3 | G23: Sensitize all Basic Education stakeholders in the state on the relevance of revised Basic education curriculum | H23: All the three senatorial zone in the state will receive the information | I23: State level | N23: 45962 | O23: 45688 | P23: 4739523.4 | Q23: =F23*P23 -> 14218570 | R23: Request for quotation | S23: 0 | T23: 14218570 | U23: 0 | W23: 0 | Y23: 0 | Z23: =Q23-SUM(S23:U23, W23,Y23) -> -0.0019999985
C24: 2.1.4 | D24: Teacher Training to improve curriculum implementation at the three senatorial zones in the State | E24: To prepare teachers for effective implementation of curriculum | F24: 3 | G24: train teachers on the implementation of the revised Basic education curriculum | H24: Selected Teachers will be trained | I24: State level | N24: 45962 | O24: 45688 | P24: 4739523.4 | Q24: =F24*P24 -> 14218570 | R24: Request for quotation | S24: 0 | T24: 14218570 | U24: 0 | W24: 0 | Y24: 0 | Z24: =Q24-SUM(S24:U24, W24,Y24) -> -0.0019999985
C25: 2.1.5 | D25: Monitoring and evaluation/ Tracking of curriculum implementation for the 23 LGAs | E25: To monitor the procure and distribution of revised Basic education curriculum | F25: 23 | G25: Track the implementation of the revised Basic education curriculum | H25: Effective implementation will be achieved | I25: State level | N25: 45962 | O25: 45688 | P25: 309099.36 | Q25: =F25*P25 -> 7109285.2 | R25: Request for quotation | S25: 0 | T25: 7109285.2 | U25: 0 | W25: 0 | Y25: 0 | Z25: =Q25-SUM(S25:U25, W25,Y25) -> 0.0039999299
C26: 2.1.6 | P26: 0 | Q26: =F26*P26 -> 0 | S26: 0 | T26: 0 | U26: 0 | W26: 0 | Y26: 0 | Z26: =Q26-SUM(S26:U26, W26,Y26) -> 0
C27: 2.1.7 | P27: 0 | Q27: =F27*P27 -> 0 | S27: 0 | T27: 0 | U27: 0 | W27: 0 | Y27: 0 | Z27: =Q27-SUM(S27:U27, W27,Y27) -> 0
C28: 2.1.8 | P28: 0 | Q28: =F28*P28 -> 0 | S28: 0 | T28: 0 | U28: 0 | W28: 0 | Y28: 0 | Z28: =Q28-SUM(S28:U28, W28,Y28) -> 0
C29: 2.1.9 | P29: 0 | Q29: =F29*P29 -> 0 | S29: 0 | T29: 0 | U29: 0 | W29: 0 | Y29: 0 | Z29: =Q29-SUM(S29:U29, W29,Y29) -> 0
C30: 2.1.10 | P30: 0 | Q30: =F30*P30 -> 0 | S30: 0 | T30: 0 | U30: 0 | W30: 0 | Y30: 0 | Z30: =Q30-SUM(S30:U30, W30,Y30) -> 0
C31: 2.1.11 | P31: 0 | Q31: =F31*P31 -> 0 | S31: 0 | T31: 0 | U31: 0 | W31: 0 | Y31: 0 | Z31: =Q31-SUM(S31:U31, W31,Y31) -> 0
C32: 2.1.12 | P32: 0 | Q32: =F32*P32 -> 0 | S32: 0 | T32: 0 | U32: 0 | W32: 0 | Y32: 0 | Z32: =Q32-SUM(S32:U32, W32,Y32) -> 0
C33: 2.1.13 | P33: 0 | Q33: =F33*P33 -> 0 | S33: 0 | T33: 0 | U33: 0 | W33: 0 | Y33: 0 | Z33: =Q33-SUM(S33:U33, W33,Y33) -> 0
C34: 2.1.14 | P34: 0 | Q34: =F34*P34 -> 0 | S34: 0 | T34: 0 | U34: 0 | W34: 0 | Y34: 0 | Z34: =Q34-SUM(S34:U34, W34,Y34) -> 0
C35: 2.1.15 | P35: 0 | Q35: =F35*P35 -> 0 | S35: 0 | T35: 0 | U35: 0 | W35: 0 | Y35: 0 | Z35: =Q35-SUM(S35:U35, W35,Y35) -> 0
C36: 2.1.16 | P36: 0 | Q36: =F36*P36 -> 0 | S36: 0 | T36: 0 | U36: 0 | W36: 0 | Y36: 0 | Z36: =Q36-SUM(S36:U36, W36,Y36) -> 0
C37: 2.1.17 | P37: 0 | Q37: =F37*P37 -> 0 | S37: 0 | T37: 0 | U37: 0 | W37: 0 | Y37: 0 | Z37: =Q37-SUM(S37:U37, W37,Y37) -> 0
... C50: 2.1.30 | P50: 0 | Q50: =F50*P50 -> 0 | S50: 0 | T50: 0 | U50: 0 | W50: 0 | Y50: 0 | Z50: =Q50-SUM(S50:U50, W50,Y50) -> 0
C51: TOTAL | Q51: =SUM(Q21:Q50) -> 1.421857e+08 | S51: =SUM(S21:S50) -> 0 | T51: =SUM(T21:T50) -> 1.421857e+08 | U51: =SUM(U21:U50) -> 0 | V51: =SUM(W21:W50,Y21:Y50) -> 0 | Z51: =SUM(Z21:Z50) -> -0.00043222401
C53: S/N | D53: Activity | E53: Objective | F53: Quantity | G53: Expected output | H53: Achievement indicator (% of activity completed) | I53: Target group (Select from the drop-down) | J53: Timeline | N53: Expected start date MM-DD-YYYY | O53: Expected due date MM-DD-YYYY | P53: Unit cost | Q53: Total cost (No input required) | R53: Implementation strategy (Select from the drop-down list) | S53: Resource mapping | Z53: Funding gap (No input required) | AA53: Remarks
S54: Government fund | V54: Development partner 1 | X54: Development partner 2
J55: Q1 | K55: Q2 | L55: Q3 | M55: Q4 | S55: State education budget | T55: UBEC matching grant | U55: Unconditional grants/Emergency funds | V55: Name | W55: Amount | X55: Name | Y55: Amount
C56: Priority initiative 2.2: Provision of adequate Teaching and Learning Materials (TLMs) for schools (Hope-EDU DLI)
C57: 2.2.1 | D57: ='Infrastructure Projects'!D1422 -> PROCUREMENT OF LITERACY AND NUMERACY TEXT/WORKBOOKS FOR PRIMARY SCHOOLS | E57: Providing sufficient TLMs to Basic Schools (Ratio 1:1 for the selected schools) | F57: 80000 | G57: 80,000No. TLMs will be delivered | H57: 100% Completion | I57: Schools | N57: 45962 | O57: 45688 | P57: ='Infrastructure Projects'!P1421 -> 721626000 | S57: 0 | T57: 722400000 | U57: 0 | W57: 0 | Y57: 0 | Z57: =Q57-SUM(S57:U57, W57,Y57) -> -722400000
C58: 2.2.2 | F58: 1 | P58: 722400000 | Q58: =F58*P58 -> 722400000 | S58: 0 | T58: 0 | U58: 0 | W58: 0 | Y58: 0 | Z58: =Q58-SUM(S58:U58, W58,Y58) -> 722400000
...

Sheet Pillar 3 - Systems Optimization
B2: Click to return to welcome page
B4: Pillar 3: Optimize institutional systems for quality service delivery
H6: HOPE-DLI | I6: UBE Pillar
C7: Click to move to each sub-theme
C8: Priority initiative 3.1: Optimize organizational structure, guidelines, and personnel capacity to effectively deliver on mandate and impact
C9: Priority initiative 3.2: Ensure transparent and effective financial management at state and LGA levels
C10: Priority initiative 3.3: Strengthen SUBEB’s brand reputation with stakeholders through strategic engagements, media, and other activities
C11: Priority initiative 3.4: Improve coordination and implementation of basic education programs with MoE, LGEAs, UBEC and other stakeholders
C12: Enabler: Strengthen performance management, and routine monitoring and evaluation of Basic Education Programs
C13: Enabler: Instituting a framework for quality assurance to improve access to basic education
C15: S/N | D15: Activity | E15: Quantity (Insert only numeric values) | F15: Objective | G15: Expected output | H15: Achievement indicator | I15: Target group (Select from the drop-down) | J15: Timeline (Shade as applicable) | N15: Expected start date MM-DD-YYYY | O15: Expected due date MM-DD-YYYY | P15: Unit Cost | Q15: Total cost (No input required) | R15: Implementation strategy (Select from the drop-down list) | S15: Resource mapping | Z15: Funding gap (No input required) | AA15: Remarks
S16: Government fund | V16: Development partner 1 | X16: Development partner 2
J17: Q1 | K17: Q2 | L17: Q3 | M17: Q4 | S17: State education budget | T17: UBEC matching grant | U17: Unconditional grants/Emergency funds | V17: Name | W17: Amount | X17: Name | Y17: Amount
C19: Priority initiative 3.1: Optimize organizational structure, guidelines, and personnel capacity to effectively deliver on mandate and impact
C20: 3.1.1 | D20: Conduct workshop to update organizational structure and operational guidelines | P20: 0 | Q20: =E20*P20 -> 0 | S20: 0 | T20: 0 | U20: 0 | W20: 0 | Y20: 0 | Z20: =Q20-SUM(S20:U20, W20,Y20) -> 0
C21: 3.1.2 | P21: 0 | Q21: =E21*P21 -> 0 | S21: 0 | T21: 0 | U21: 0 | W21: 0 | Y21: 0 | Z21: =Q21-SUM(S21:U21, W21,Y21) -> 0
C22: 3.1.3 | P22: 0 | Q22: =E22*P22 -> 0 | S22: 0 | T22: 0 | U22: 0 | W22: 0 | Y22: 0 | Z22: =Q22-SUM(S22:U22, W22,Y22) -> 0
C23: 3.1.4 | P23: 0 | Q23: =E23*P23 -> 0 | S23: 0 | T23: 0 | U23: 0 | W23: 0 | Y23: 0 | Z23: =Q23-SUM(S23:U23, W23,Y23) -> 0
C24: 3.1.5 | P24: 0 | Q24: =E24*P24 -> 0 | S24: 0 | T24: 0 | U24: 0 | W24: 0 | Y24: 0 | Z24: =Q24-SUM(S24:U24, W24,Y24) -> 0
C25: 3.1.6 | P25: 0 | Q25: =E25*P25 -> 0 | S25: 0 | T25: 0 | U25: 0 | W25: 0 | Y25: 0 | Z25: =Q25-SUM(S25:U25, W25,Y25) -> 0
C26: 3.1.7 | P26: 0 | Q26: =E26*P26 -> 0 | S26: 0 | T26: 0 | U26: 0 | W26: 0 | Y26: 0 | Z26: =Q26-SUM(S26:U26, W26,Y26) -> 0
C27: 3.1.8 | P27: 0 | Q27: =E27*P27 -> 0 | S27: 0 | T27: 0 | U27: 0 | W27: 0 | Y27: 0 | Z27: =Q27-SUM(S27:U27, W27,Y27) -> 0
C28: 3.1.9 | P28: 0 | Q28: =E28*P28 -> 0 | S28: 0 | T28: 0 | U28: 0 | W28: 0 | Y28: 0 | Z28: =Q28-SUM(S28:U28, W28,Y28) -> 0
C29: 3.1.10 | P29: 0 | Q29: =E29*P29 -> 0 | S29: 0 | T29: 0 | U29: 0 | W29: 0 | Y29: 0 | Z29: =Q29-SUM(S29:U29, W29,Y29) -> 0
C30: 3.1.11 | P30: 0 | Q30: =E30*P30 -> 0 | S30: 0 | T30: 0 | U30: 0 | W30: 0 | Y30: 0 | Z30: =Q30-SUM(S30:U30, W30,Y30) -> 0
C31: 3.1.12 | P31: 0 | Q31: =E31*P31 -> 0 | S31: 0 | T31: 0 | U31: 0 | W31: 0 | Y31: 0 | Z31: =Q31-SUM(S31:U31, W31,Y31) -> 0
C32: 3.1.13 | P32: 0 | Q32: =E32*P32 -> 0 | S32: 0 | T32: 0 | U32: 0 | W32: 0 | Y32: 0 | Z32: =Q32-SUM(S32:U32, W32,Y32) -> 0
... C49: 3.1.30 | P49: 0 | Q49: =E49*P49 -> 0 | S49: 0 | T49: 0 | U49: 0 | W49: 0 | Y49: 0 | Z49: =Q49-SUM(S49:U49, W49,Y49) -> 0
C50: TOTAL | Q50: =SUM(Q20:Q49) -> 0 | S50: =SUM(S20:S49) -> 0 | T50: =SUM(T20:T49) -> 0 | U50: =SUM(U20:U49) -> 0 | V50: =SUM(W20:W49,Y20:Y49) -> 0 | Z50: =SUM(Z20:Z49) -> 0
C52: S/N | D52: Activity | E52: Quantity (Insert only numeric values) | F52: Objective | G52: Expected output | H52: Achievement indicator | I52: Target group (Select from the drop-down) | J52: Timeline (Shade as applicable) | N52: Expected start date MM-DD-YYYY | O52: Expected due date MM-DD-YYYY | P52: Unit cost | Q52: Total cost (No input required) | R52: Implementation strategy (Select from the drop-down list) | S52: Resource mapping | Z52: Funding gap (No input required) | AA52: Remarks
S53: Government fund | V53: Development partner 1 | X53: Development partner 2
J54: Q1 | K54: Q2 | L54: Q3 | M54: Q4 | S54: State education budget | T54: UBEC matching grant | U54: Unconditional grants/Emergency funds | V54: Name | W54: Amount | X54: Name | Y54: Amount
C55: Priority initiative 3.2: Ensure transparent and effective financial management at state and LGA levels
C56: 3.2.1 | D56: Strengthen financial reporting systems at SUBEB level using digital tools | P56: 0 | Q56: =$E56*$P56 -> 0 | S56: 0 | T56: 0 | U56: 0 | W56: 0 | Y56: 0 | Z56: =Q56-SUM(S56:U56, W56,Y56) -> 0
C57: 3.2.2 | D57: Implement school grants and ensure SBMCs adopt financial accountability framework | P57: 0 | Q57: =$E57*$P57 -> 0 | S57: 0 | T57: 0 | U57: 0 | W57: 0 | Y57: 0 | Z57: =Q57-SUM(S57:U57, W57,Y57) -> 0
C58: 3.2.3 | P58: 0 | Q58: =$E58*$P58 -> 0 | S58: 0 | T58: 0 | U58: 0 | W58: 0 | Y58: 0 | Z58: =Q58-SUM(S58:U58, W58,Y58) -> 0
C59: 3.2.4 | P59: 0 | Q59: =$E59*$P59 -> 0 | S59: 0 | T59: 0 | U59: 0 | W59: 0 | Y59: 0 | Z59: =Q59-SUM(S59:U59, W59,Y59) -> 0
C60: 3.2.5 | P60: 0 | Q60: =$E60*$P60 -> 0 | S60: 0 | T60: 0 | U60: 0 | W60: 0 | Y60: 0 | Z60: =Q60-SUM(S60:U60, W60,Y60) -> 0
C61: 3.2.6 | P61: 0 | Q61: =$E61*$P61 -> 0 | S61: 0 | T61: 0 | U61: 0 | W61: 0 | Y61: 0 | Z61: =Q61-SUM(S61:U61, W61,Y61) -> 0
C62: 3.2.7 | P62: 0 | Q62: =$E62*$P62 -> 0 | S62: 0 | T62: 0 | U62: 0 | W62: 0 | Y62: 0 | Z62: =Q62-SUM(S62:U62, W62,Y62) -> 0
...

Sheet Unit Cost Set-Up
B2: Review the list below. Add additional cost items or Adjust the unit cost where necessary. Please make all entries within the table
B3: State-specific Cost Assumptions
B4: Cost Items | C4: Unit Cost (₦)
B5: Construction of 2 classrooms with 2 playrooms, 4 toilets and interlocking | C5: 26521567
B30: •
B31: •
B32: •
B33: •
B34: •
B35: •
B36: •
B37: •
B38: •
B39: •
B40: •
B41: •
... B144: •

Sheet Activity costing 
B2: Pillar 1 | C2: Expand access to UBE especially for rural and undeserved populations
B3: Pillar 2 | C3: Enhance Quality of Teaching and Learning
B4: Pillar 3 | C4: Reform and Strengthen Basic Education Financing
B5: Pillar 4 | C5: Optimize institutional systems for quality service delivery
B6: Enablers
C9: Pillar 1 | D9: Expand access to UBE especially for rural and undeserved populations
C10: Activity | D10: Furniture | F10: Grand Total
C11: Input | D11: Quantity | E11: Frequency | F11: Unit cost | G11: Total
C12: Procurement of teacher furniture | D12: 50 | E12: 1 | G12: =PRODUCT(D12:F12) -> 50
F13: =VLOOKUP(C13,#REF!, 2, FALSE) -> #REF! | G13: =PRODUCT(D13:F13) -> #REF!
F14: =VLOOKUP(C14,#REF!, 2, FALSE) -> #REF! | G14: =PRODUCT(D14:F14) -> #REF!
F15: =VLOOKUP(C15,#REF!, 2, FALSE) -> #REF! | G15: =PRODUCT(D15:F15) -> #REF!
F16: =VLOOKUP(C16,#REF!, 2, FALSE) -> #REF! | G16: =PRODUCT(D16:F16) -> #REF!
G17: =PRODUCT(D17:F17) -> 0
C22: Activity | D22: ='Pillar 1 - Access'!E36 -> 0 | F22: Grand Total | G22: =SUM(G24:G32) -> #REF!
C23: Input | D23: Quantity | E23: Frequency | F23: Unit cost | G23: Total
F24: =VLOOKUP(C24,#REF!, 2, FALSE) -> #REF! | G24: =PRODUCT(D24:F24) -> #REF!
F25: =VLOOKUP(C25,#REF!, 2, FALSE) -> #REF! | G25: =PRODUCT(D25:F25) -> #REF!
F26: =VLOOKUP(C26,#REF!, 2, FALSE) -> #REF! | G26: =PRODUCT(D26:F26) -> #REF!
F27: =VLOOKUP(C27,#REF!, 2, FALSE) -> #REF! | G27: =PRODUCT(D27:F27) -> #REF!
F28: =VLOOKUP(C28,#REF!, 2, FALSE) -> #REF! | G28: =PRODUCT(D28:F28) -> #REF!
F29: =VLOOKUP(C29,#REF!, 2, FALSE) -> #REF! | G29: =PRODUCT(D29:F29) -> #REF!
F30: =VLOOKUP(C30,#REF!, 2, FALSE) -> #REF! | G30: =PRODUCT(D30:F30) -> #REF!
F31: =VLOOKUP(C31,#REF!, 2, FALSE) -> #REF! | G31: =PRODUCT(D31:F31) -> #REF!
F32: =VLOOKUP(C32,#REF!, 2, FALSE) -> #REF! | G32: =PRODUCT(D32:F32) -> #REF!
C34: Activity | D34: 0 | F34: Grand Total
C35: Input | D35: Quantity | E35: Frequency | F35: Unit cost | G35: Total
C45: Activity | D45: 0 | F45: Grand Total
C46: Input | D46: Quantity | E46: Frequency | F46: Unit cost | G46: Total
C57: Activity | D57: 0 | F57: Grand Total
C58: Input | D58: Quantity | E58: Frequency | F58: Unit cost | G58: Total
C69: Activity | D69: 0 | F69: Grand Total
C70: Input | D70: Quantity | E70: Frequency | F70: Unit cost | G70: Total
C80: Activity | D80: 0 | F80: Grand Total
C81: Input | D81: Quantity | E81: Frequency | F81: Unit cost | G81: Total
C92: Activity | D92: 0 | F92: Grand Total
C93: Input | D93: Quantity | E93: Frequency | F93: Unit cost | G93: Total
C104: Activity | D104: 0 | F104: Grand Total
C105: Input | D105: Quantity | E105: Frequency | F105: Unit cost | G105: Total
C116: Activity | D116: Activity | F116: Grand Total
...

Sheet Total budget summary
B1: Total Available UBE Funds
B2: Total Matching Grant Accessed | C2: ='Welcome Page'!C8 -> 7.1092852e+09
B3: Total Matching Grant Allocated in Action Plan | C3: =SUM(D38:D46) -> 7.1092852e+09
B4: Total State Budget for BEAP activities (excludes matching grant) | C4: ='Pillar 1 - Access'!S201+'Pillar 2 - Quality'!O227+'Pillar 3 - Systems Optimization'!S232 -> 989400000
B5: Total Donor funding for planned BEAP activities | C5: ='Pillar 1 - Access'!V201+'Pillar 2 - Quality'!R227+'Pillar 3 - Systems Optimization'!V232 -> 0
B6: Total Unconditional Grant/ Emergency funds for planned BEAP activities | C6: ='Pillar 1 - Access'!U201+'Pillar 2 - Quality'!Q227+'Pillar 3 - Systems Optimization'!U232 -> 230000000
B7: Total | C7: =SUM(C3:D6) -> 8.3286852e+09
B9: Summary of Funds Allocated by Pillar
B10: Pillar | C10: Total cost | D10: Percentage of total budget
B11: Pillar 1: Expand access to UBE esp for rural and undeserved populations | C11: ='Pillar 1 - Access'!Q201 -> 5.1063128e+09 | D11: =IFERROR(C11/C7,"") -> 0.61309952
B12: ='Pillar 1 - Access'!C17 -> Priority initiative 1.1: Provide safe and adequate infrastructure for learning environments (Hope-EDU DLI) | C12: ='Pillar 1 - Access'!O28 -> 4.6086629e+09
B13: ='Pillar 1 - Access'!C33 -> Priority initiative 1.2: Expand enrollment of out-of-school children into the formal education system (Hope-EDU DLI) | C13: ='Pillar 1 - Access'!Q66 -> 0
B14: ='Pillar 1 - Access'!C71 -> Priority initiative 1.3 (Matching grant): Improve retention with incentives such as School Based Management Committee (SMBC) initiatives | C14: ='Pillar 1 - Access'!Q123 -> 3.5546426e+08
B15: ='Pillar 1 - Access'!C128 -> Enabler (Matching grant): Supervision and Project monitoring of ongoing infrastructure activities | C15: ='Pillar 1 - Access'!Q159 -> 1.421857e+08
B16: ='Pillar 1 - Access'!C166 -> Enabler: Partnerships and cross-sector collaboration to expand access to basic education | C16: ='Pillar 1 - Access'!P197 -> 0
B18: Pillar 2: Enhance quality of teaching and learning | C18: ='Pillar 2 - Quality'!N227 -> 2.6027789e+09 | D18: =IFERROR(C18/C7,"") -> 0.31250778
B19: ='Pillar 2 - Quality'!C20 -> Priority initiative 2.1 (Matching grant): Ensure implementation of revised basic education curriculum across schools | C19: ='Pillar 2 - Quality'!Q51 -> 1.421857e+08
B20: ='Pillar 2 - Quality'!C56 -> Priority initiative 2.2: Provision of adequate Teaching and Learning Materials (TLMs) for schools (Hope-EDU DLI) | C20: ='Pillar 2 - Quality'!Q87 -> 722400000
B21: ='Pillar 2 - Quality'!C93 -> Priority initiative 2.3: Teacher/ education managers training and capacity building (Hope-EDU DLI) | C21: ='Pillar 2 - Quality'!Q124 -> 0
B22: ='Pillar 2 - Quality'!C204 -> Matching Grant Intervention: Sports Development | C22: ='Pillar 2 - Quality'!I209 -> 1.421857e+08
B23: ='Pillar 2 - Quality'!C214 -> Matching Grant Intervention: Green School and Climate Change and Safeguards | C23: ='Pillar 2 - Quality'!I224 -> 1.421857e+08
B24: ='Pillar 2 - Quality'!C132 -> Enabler (Matching grant): Quality Assurance monitoring | C24: ='Pillar 2 - Quality'!P163 -> 1.0895755e+08
B25: ='Pillar 2 - Quality'!C168 -> Enabler (Matching grant): Leveraging digitalization to improve the quality of basic education (ICT and Data Platform) | C25: ='Pillar 2 - Quality'!Q199 -> 3.5546426e+08
B27: Pillar 3: Optimize institutional systemns for quality service delivery | C27: ='Pillar 3 - Systems Optimization'!Q232 -> 3.8869242e+08 | D27: =IFERROR(C27/C7,"") -> 0.046669121
B28: ='Pillar 3 - Systems Optimization'!C19 -> Priority initiative 3.1: Optimize organizational structure, guidelines, and personnel capacity to effectively deliver on mandate and impact | C28: ='Pillar 3 - Systems Optimization'!Q50 -> 0
B29: ='Pillar 3 - Systems Optimization'!C55 -> Priority initiative 3.2: Ensure transparent and effective financial management at state and LGA levels | C29: ='Pillar 3 - Systems Optimization'!Q86 -> 0
B30: ='Pillar 3 - Systems Optimization'!C91 -> Priority initiative 3.3: Strengthen SUBEB’s brand reputation with stakeholders through strategic engagements, media, and other activities | C30: ='Pillar 3 - Systems Optimization'!Q122 -> 0
B31: ='Pillar 3 - Systems Optimization'!C127 -> Priority initiative 3.4: Improve coordination and implementation of basic education programs with MoE, LGEAs, UBEC and other stakeholders | C31: ='Pillar 3 - Systems Optimization'!Q158 -> 0
B32: ='Pillar 3 - Systems Optimization'!C163 -> Enabler (Matching grant): Strengthen performance management, and routine monitoring and evaluation of Basic Education Programs (Planning & Education Management Information Systems) | C32: ='Pillar 3 - Systems Optimization'!Q194 -> 1.421857e+08
B33: ='Pillar 3 - Systems Optimization'!C199 -> Enabler: Instituting a framework for quality assurance to improve access to basic education | C33: ='Pillar 3 - Systems Optimization'!P230 -> 2.4650671e+08
B36: Summary of Funds Allocated Across UBEC Matching Grant Utilization Domains (per guidelines)
B37: Description | C37: Percentage | D37: Amount
B38: Infastructructure projects and TLMs | C38: =(IFERROR(D38/$D$47,0)) -> 0.75 | D38: ='Infrastructure Projects'!L9 -> 5.3319639e+09
B39: Purchase and distribution of curriculum | C39: =(IFERROR(D39/$D$47,0)) -> 0.02 | D39: ='Pillar 2 - Quality'!Q51 -> 1.421857e+08
B40: ICT and Data Platform | C40: =(IFERROR(D40/$D$47,0)) -> 0.05 | D40: ='Pillar 2 - Quality'!Q199 -> 3.5546426e+08
B41: SBMC | C41: =(IFERROR(D41/$D$47,0)) -> 0.05 | D41: ='Pillar 1 - Access'!Q123 -> 3.5546426e+08
B42: Planning & Education Management Information systems | C42: =(IFERROR(D42/$D$47,0)) -> 0.02 | D42: ='Pillar 3 - Systems Optimization'!Q194 -> 1.421857e+08
B43: Greening Schools Climate Change and Safeguards | C43: =(IFERROR(D43/$D$47,0)) -> 0.02 | D43: ='Pillar 2 - Quality'!I224 -> 1.421857e+08
B44: Sports Development | C44: =(IFERROR(D44/$D$47,0)) -> 0.02 | D44: ='Pillar 2 - Quality'!I209 -> 1.421857e+08
B45: Quality Assurance Monitoring | C45: =(IFERROR(D45/$D$47,0)) -> 0.05 | D45: =SUM(C24,C33) -> 3.5546426e+08
...

Sheet HOPE-DLI 
B2: Pillars | C2: Disbursement Linked Indicators (DLIs) | D2: DLIs Expected Results | E2: Sample activities
B3: Expand Access to UBE | C3: DLI 4: Number of new primary classrooms created through community participation | D3: Government-community agreements signed to create new classrooms | E3: Construction of 2 Storey building blocks of 4 Classrooms, 3 Offices, 1 Library/Computer lab, Store, Playroom and 10 Water Closet
D4: 13,000 new classrooms created
C5: DLI 5: Number of out-of-school children who complete NFBE program | D5: 10,000 NFLCs have Management Committee, Teachers, and TLMs | E5: Implement open school activities in nomadic and high density IDP camps across 3 LGAs
D6: 1,500,000 out-of-school children complete NFBE program
